Workbook

Sheet Summary
A1: Test execution summary
A2: Run date 2026-10-07. All figures below are formulas over the "Test Cases" and "Automated Run" sheets.
A4: Catalogue status | B4: Count | C4: % of cases
A5: Pass | B5: =COUNTIF('Test Cases'!$H$5:$H$168,"Pass") -> 140 | C5: =IF($B$9=0,0,B5/$B$9) -> 0.85365854
A6: Fail | B6: =COUNTIF('Test Cases'!$H$5:$H$168,"Fail") -> 0 | C6: =IF($B$9=0,0,B6/$B$9) -> 0
A7: Blocked | B7: =COUNTIF('Test Cases'!$H$5:$H$168,"Blocked") -> 4 | C7: =IF($B$9=0,0,B7/$B$9) -> 0.024390244
A8: Not Run | B8: =COUNTIF('Test Cases'!$H$5:$H$168,"Not Run") -> 20 | C8: =IF($B$9=0,0,B8/$B$9) -> 0.12195122
A9: Total test cases | B9: =SUM(B5:B8) -> 164 | C9: =SUM(C5:C8) -> 1
A10: Pass rate of executed cases | B10: =IF((B5+B6)=0,0,B5/(B5+B6)) -> 1
A12: Automated tests (this run) | B12: Executed | C12: Passed | D12: Failed | E12: Pass rate
A13: Unit | B13: =COUNTIF('Automated Run'!$B$4:$B$221,"Unit") -> 44 | C13: =COUNTIFS('Automated Run'!$B$4:$B$221,"Unit",'Automated Run'!$E$4:$E$221,"Pass") -> 44 | D13: =COUNTIFS('Automated Run'!$B$4:$B$221,"Unit",'Automated Run'!$E$4:$E$221,"Fail") -> 0 | E13: =IF(B13=0,0,C13/B13) -> 1
A14: Integration | B14: =COUNTIF('Automated Run'!$B$4:$B$221,"Integration") -> 21 | C14: =COUNTIFS('Automated Run'!$B$4:$B$221,"Integration",'Automated Run'!$E$4:$E$221,"Pass") -> 21 | D14: =COUNTIFS('Automated Run'!$B$4:$B$221,"Integration",'Automated Run'!$E$4:$E$221,"Fail") -> 0 | E14: =IF(B14=0,0,C14/B14) -> 1
A15: API | B15: =COUNTIF('Automated Run'!$B$4:$B$221,"API") -> 9 | C15: =COUNTIFS('Automated Run'!$B$4:$B$221,"API",'Automated Run'!$E$4:$E$221,"Pass") -> 9 | D15: =COUNTIFS('Automated Run'!$B$4:$B$221,"API",'Automated Run'!$E$4:$E$221,"Fail") -> 0 | E15: =IF(B15=0,0,C15/B15) -> 1
A16: Security | B16: =COUNTIF('Automated Run'!$B$4:$B$221,"Security") -> 12 | C16: =COUNTIFS('Automated Run'!$B$4:$B$221,"Security",'Automated Run'!$E$4:$E$221,"Pass") -> 12 | D16: =COUNTIFS('Automated Run'!$B$4:$B$221,"Security",'Automated Run'!$E$4:$E$221,"Fail") -> 0 | E16: =IF(B16=0,0,C16/B16) -> 1
A17: PostgreSQL | B17: =COUNTIF('Automated Run'!$B$4:$B$221,"PostgreSQL") -> 8 | C17: =COUNTIFS('Automated Run'!$B$4:$B$221,"PostgreSQL",'Automated Run'!$E$4:$E$221,"Pass") -> 8 | D17: =COUNTIFS('Automated Run'!$B$4:$B$221,"PostgreSQL",'Automated Run'!$E$4:$E$221,"Fail") -> 0 | E17: =IF(B17=0,0,C17/B17) -> 1
A18: Functional | B18: =COUNTIF('Automated Run'!$B$4:$B$221,"Functional") -> 124 | C18: =COUNTIFS('Automated Run'!$B$4:$B$221,"Functional",'Automated Run'!$E$4:$E$221,"Pass") -> 121 | D18: =COUNTIFS('Automated Run'!$B$4:$B$221,"Functional",'Automated Run'!$E$4:$E$221,"Fail") -> 0 | E18: =IF(B18=0,0,C18/B18) -> 0.97580645
A19: Total | B19: =SUM(B13:B18) -> 218 | C19: =SUM(C13:C18) -> 215 | D19: =SUM(D13:D18) -> 0 | E19: =IF(B19=0,0,C19/B19) -> 0.98623853
A20: Quality gate | B20: Measured | C20: Target | D20: Result
A21: Line coverage | B21: 99.45% | C21: ≥ 80% | D21: Pass
A22: Branch coverage | B22: 92.26% | C22: ≥ 70% | D22: Pass
A23: Function coverage | B23: 97.65% | C23: ≥ 80% | D23: Pass
A24: Lint (ESLint) | B24: 0 errors | C24: 0 errors | D24: Pass
A25: Load test p95 latency | B25: 114.6 ms | C25: ≤ 300 ms | D25: Pass
A26: Load test throughput (1 process, 25 concurrent) | B26: 338.1 req/s | C26: informational | D26: —
A27: Load test error rate | B27: 0.00% | C27: ≤ 1% | D27: Pass
A29: Module | B29: Cases | C29: Pass | D29: Fail | E29: Blocked | F29: Not Run
A30: Authentication and session | B30: =COUNTIF('Test Cases'!$B$5:$B$168,A30) -> 20 | C30: =COUNTIFS('Test Cases'!$B$5:$B$168,$A30,'Test Cases'!$H$5:$H$168,"Pass") -> 19 | D30: =COUNTIFS('Test Cases'!$B$5:$B$168,$A30,'Test Cases'!$H$5:$H$168,"Fail") -> 0 | E30: =COUNTIFS('Test Cases'!$B$5:$B$168,$A30,'Test Cases'!$H$5:$H$168,"Blocked") -> 1 | F30: =COUNTIFS('Test Cases'!$B$5:$B$168,$A30,'Test Cases'!$H$5:$H$168,"Not Run") -> 0
A31: Authorisation (RBAC / ABAC) | B31: =COUNTIF('Test Cases'!$B$5:$B$168,A31) -> 10 | C31: =COUNTIFS('Test Cases'!$B$5:$B$168,$A31,'Test Cases'!$H$5:$H$168,"Pass") -> 9 | D31: =COUNTIFS('Test Cases'!$B$5:$B$168,$A31,'Test Cases'!$H$5:$H$168,"Fail") -> 0 | E31: =COUNTIFS('Test Cases'!$B$5:$B$168,$A31,'Test Cases'!$H$5:$H$168,"Blocked") -> 1 | F31: =COUNTIFS('Test Cases'!$B$5:$B$168,$A31,'Test Cases'!$H$5:$H$168,"Not Run") -> 0
A32: Customer 360, data enrichment and MDM | B32: =COUNTIF('Test Cases'!$B$5:$B$168,A32) -> 10 | C32: =COUNTIFS('Test Cases'!$B$5:$B$168,$A32,'Test Cases'!$H$5:$H$168,"Pass") -> 10 | D32: =COUNTIFS('Test Cases'!$B$5:$B$168,$A32,'Test Cases'!$H$5:$H$168,"Fail") -> 0 | E32: =COUNTIFS('Test Cases'!$B$5:$B$168,$A32,'Test Cases'!$H$5:$H$168,"Blocked") -> 0 | F32: =COUNTIFS('Test Cases'!$B$5:$B$168,$A32,'Test Cases'!$H$5:$H$168,"Not Run") -> 0
A33: Lead scoring, NBA and benefits | B33: =COUNTIF('Test Cases'!$B$5:$B$168,A33) -> 9 | C33: =COUNTIFS('Test Cases'!$B$5:$B$168,$A33,'Test Cases'!$H$5:$H$168,"Pass") -> 9 | D33: =COUNTIFS('Test Cases'!$B$5:$B$168,$A33,'Test Cases'!$H$5:$H$168,"Fail") -> 0 | E33: =COUNTIFS('Test Cases'!$B$5:$B$168,$A33,'Test Cases'!$H$5:$H$168,"Blocked") -> 0 | F33: =COUNTIFS('Test Cases'!$B$5:$B$168,$A33,'Test Cases'!$H$5:$H$168,"Not Run") -> 0
A34: Journeys and contact compliance | B34: =COUNTIF('Test Cases'!$B$5:$B$168,A34) -> 14 | C34: =COUNTIFS('Test Cases'!$B$5:$B$168,$A34,'Test Cases'!$H$5:$H$168,"Pass") -> 14 | D34: =COUNTIFS('Test Cases'!$B$5:$B$168,$A34,'Test Cases'!$H$5:$H$168,"Fail") -> 0 | E34: =COUNTIFS('Test Cases'!$B$5:$B$168,$A34,'Test Cases'!$H$5:$H$168,"Blocked") -> 0 | F34: =COUNTIFS('Test Cases'!$B$5:$B$168,$A34,'Test Cases'!$H$5:$H$168,"Not Run") -> 0
A35: Voice bot and telesales handoff | B35: =COUNTIF('Test Cases'!$B$5:$B$168,A35) -> 7 | C35: =COUNTIFS('Test Cases'!$B$5:$B$168,$A35,'Test Cases'!$H$5:$H$168,"Pass") -> 7 | D35: =COUNTIFS('Test Cases'!$B$5:$B$168,$A35,'Test Cases'!$H$5:$H$168,"Fail") -> 0 | E35: =COUNTIFS('Test Cases'!$B$5:$B$168,$A35,'Test Cases'!$H$5:$H$168,"Blocked") -> 0 | F35: =COUNTIFS('Test Cases'!$B$5:$B$168,$A35,'Test Cases'!$H$5:$H$168,"Not Run") -> 0
A36: Quote → pay → issue → e-certificate | B36: =COUNTIF('Test Cases'!$B$5:$B$168,A36) -> 10 | C36: =COUNTIFS('Test Cases'!$B$5:$B$168,$A36,'Test Cases'!$H$5:$H$168,"Pass") -> 10 | D36: =COUNTIFS('Test Cases'!$B$5:$B$168,$A36,'Test Cases'!$H$5:$H$168,"Fail") -> 0 | E36: =COUNTIFS('Test Cases'!$B$5:$B$168,$A36,'Test Cases'!$H$5:$H$168,"Blocked") -> 0 | F36: =COUNTIFS('Test Cases'!$B$5:$B$168,$A36,'Test Cases'!$H$5:$H$168,"Not Run") -> 0
A37: Partners and partner API | B37: =COUNTIF('Test Cases'!$B$5:$B$168,A37) -> 9 | C37: =COUNTIFS('Test Cases'!$B$5:$B$168,$A37,'Test Cases'!$H$5:$H$168,"Pass") -> 9 | D37: =COUNTIFS('Test Cases'!$B$5:$B$168,$A37,'Test Cases'!$H$5:$H$168,"Fail") -> 0 | E37: =COUNTIFS('Test Cases'!$B$5:$B$168,$A37,'Test Cases'!$H$5:$H$168,"Blocked") -> 0 | F37: =COUNTIFS('Test Cases'!$B$5:$B$168,$A37,'Test Cases'!$H$5:$H$168,"Not Run") -> 0
A38: Rules engine and maker-checker | B38: =COUNTIF('Test Cases'!$B$5:$B$168,A38) -> 10 | C38: =COUNTIFS('Test Cases'!$B$5:$B$168,$A38,'Test Cases'!$H$5:$H$168,"Pass") -> 9 | D38: =COUNTIFS('Test Cases'!$B$5:$B$168,$A38,'Test Cases'!$H$5:$H$168,"Fail") -> 0 | E38: =COUNTIFS('Test Cases'!$B$5:$B$168,$A38,'Test Cases'!$H$5:$H$168,"Blocked") -> 0 | F38: =COUNTIFS('Test Cases'!$B$5:$B$168,$A38,'Test Cases'!$H$5:$H$168,"Not Run") -> 1
A39: Claims FNOL | B39: =COUNTIF('Test Cases'!$B$5:$B$168,A39) -> 5 | C39: =COUNTIFS('Test Cases'!$B$5:$B$168,$A39,'Test Cases'!$H$5:$H$168,"Pass") -> 5 | D39: =COUNTIFS('Test Cases'!$B$5:$B$168,$A39,'Test Cases'!$H$5:$H$168,"Fail") -> 0 | E39: =COUNTIFS('Test Cases'!$B$5:$B$168,$A39,'Test Cases'!$H$5:$H$168,"Blocked") -> 0 | F39: =COUNTIFS('Test Cases'!$B$5:$B$168,$A39,'Test Cases'!$H$5:$H$168,"Not Run") -> 0
A40: Privacy, encryption and audit | B40: =COUNTIF('Test Cases'!$B$5:$B$168,A40) -> 7 | C40: =COUNTIFS('Test Cases'!$B$5:$B$168,$A40,'Test Cases'!$H$5:$H$168,"Pass") -> 5 | D40: =COUNTIFS('Test Cases'!$B$5:$B$168,$A40,'Test Cases'!$H$5:$H$168,"Fail") -> 0 | E40: =COUNTIFS('Test Cases'!$B$5:$B$168,$A40,'Test Cases'!$H$5:$H$168,"Blocked") -> 0 | F40: =COUNTIFS('Test Cases'!$B$5:$B$168,$A40,'Test Cases'!$H$5:$H$168,"Not Run") -> 2
A41: Operations, jobs and events | B41: =COUNTIF('Test Cases'!$B$5:$B$168,A41) -> 5 | C41: =COUNTIFS('Test Cases'!$B$5:$B$168,$A41,'Test Cases'!$H$5:$H$168,"Pass") -> 2 | D41: =COUNTIFS('Test Cases'!$B$5:$B$168,$A41,'Test Cases'!$H$5:$H$168,"Fail") -> 0 | E41: =COUNTIFS('Test Cases'!$B$5:$B$168,$A41,'Test Cases'!$H$5:$H$168,"Blocked") -> 1 | F41: =COUNTIFS('Test Cases'!$B$5:$B$168,$A41,'Test Cases'!$H$5:$H$168,"Not Run") -> 2
... A46: Additional cases (assisted sales and review findings) | B46: =COUNTIF('Test Cases'!$B$5:$B$168,A46) -> 9 | C46: =COUNTIFS('Test Cases'!$B$5:$B$168,$A46,'Test Cases'!$H$5:$H$168,"Pass") -> 9 | D46: =COUNTIFS('Test Cases'!$B$5:$B$168,$A46,'Test Cases'!$H$5:$H$168,"Fail") -> 0 | E46: =COUNTIFS('Test Cases'!$B$5:$B$168,$A46,'Test Cases'!$H$5:$H$168,"Blocked") -> 0 | F46: =COUNTIFS('Test Cases'!$B$5:$B$168,$A46,'Test Cases'!$H$5:$H$168,"Not Run") -> 0
A47: Total | B47: =SUM(B30:B46) -> 164 | C47: =SUM(C30:C46) -> 140 | D47: =SUM(D30:D46) -> 0 | E47: =SUM(E30:E46) -> 4 | F47: =SUM(F30:F46) -> 20
...

Sheet Functional Test Cases
A1: Functional test cases — business scenarios from user-story acceptance criteria (Given / When / Then)
A2: Each scenario is executed by the automated functional acceptance suite (test/functional/*.test.js, one test per scenario, named "US-xxx · scenario") against the real API. Run 2026-10-07.
A4: Functional TC ID | B4: Epic | C4: User Story | D4: Persona / Actor | E4: Test Scenario | F4: Pre-conditions (Given) | G4: Test Steps (When) | H4: Expected Result (Then) | I4: Actual Result | J4: Status | K4: Requirement (FR) | L4: Priority | M4: Automated test | N4: Duration (ms) | O4: Executed On
A5: FTC-001 | B5: EP-01 Data foundation and repair | C5: US-001: Ingest a partner list into golden profiles | D5: data steward (PS-06) | E5: Duplicate records for the same vehicle merge into one golden profile | F5: Given a VETC account record with plate "30a-123.45" and phone "+84912345678" And a partner_bank record with plate "30A 12345" and phone "0912 345 678" | G5: When I POST both records to /api/data/ingest with source "partner_bank" | H5: Then exactly one profile with id "30A12345" and plate "30A-123.45" exists And its phone is "0912345678" And its sources include "vetc_account" and "partner_bank" | I5: As expected — all Then/And conditions asserted by the automated scenario. | J5: Pass | K5: FR-001, FR-002, FR-003, FR-004, FR-011 | L5: Must | M5: test/functional/ep01-04-data-leads-journeys.test.js | N5: 1130.4 | O5: 2026-10-07
A6: FTC-002 | B6: EP-01 Data foundation and repair | C6: US-001: Ingest a partner list into golden profiles | D6: data steward (PS-06) | E6: Invalid plate is rejected and raised as a DQ issue | F6: Given a record with plate "30-12345" | G6: When the batch is ingested | H6: Then the response reports rejected = 1 And a DQ issue of type "invalid_plate" is open for that record id | I6: As expected — all Then/And conditions asserted by the automated scenario. | J6: Pass | K6: FR-001, FR-002, FR-003, FR-004, FR-011 | L6: Must | M6: test/functional/ep01-04-data-leads-journeys.test.js | N6: 5.4 | O6: 2026-10-07
A7: FTC-003 | B7: EP-01 Data foundation and repair | C7: US-001: Ingest a partner list into golden profiles | D7: data steward (PS-06) | E7: Batch size limit | F7: — | G7: When I post a batch of 5,001 records | H7: Then the request is rejected with a validation error | I7: As expected — all Then/And conditions asserted by the automated scenario. | J7: Pass | K7: FR-001, FR-002, FR-003, FR-004, FR-011 | L7: Must | M7: test/functional/ep01-04-data-leads-journeys.test.js | N7: 9.8 | O7: 2026-10-07
A8: FTC-004 | B8: EP-01 Data foundation and repair | C8: US-002: See how reliable an expiry date is | D8: campaign manager (PS-03) | E8: Verified certificate wins | F8: Given a vehicle has a verified certificate expiring 2027-03-01 and an inspection-cycle estimate of 2027-03-10 | G8: When the profile is built | H8: Then policy.expiryDate is "2027-03-01" And expiryMethod is "verified_certificate" with confidence 1.0 | I8: As expected — all Then/And conditions asserted by the automated scenario. | J8: Pass | K8: FR-005, FR-008 | L8: Must | M8: test/functional/ep01-04-data-leads-journeys.test.js | N8: 0.7 | O8: 2026-10-07
A9: FTC-005 | B9: EP-01 Data foundation and repair | C9: US-002: See how reliable an expiry date is | D9: campaign manager (PS-03) | E9: Agreeing weak evidence is corroborated | F9: Given only an inspection-cycle estimate (0.5) and a tag-anniversary estimate (0.25) within 21 days of each other | G9: When the profile is built | H9: Then the chosen method is "inspection_cycle" And confidence is 0.65 | I9: As expected — all Then/And conditions asserted by the automated scenario. | J9: Pass | K9: FR-005, FR-008 | L9: Must | M9: test/functional/ep01-04-data-leads-journeys.test.js | N9: 0.6 | O9: 2026-10-07
A10: FTC-006 | B10: EP-01 Data foundation and repair | C10: US-002: See how reliable an expiry date is | D10: campaign manager (PS-03) | E10: Lineage shows the evidence | F10: — | G10: When I GET /api/customers/{id}/lineage | H10: Then I see a field entry "policy.expiryDate" with its source and confidence | I10: As expected — all Then/And conditions asserted by the automated scenario. | J10: Pass | K10: FR-005, FR-008 | L10: Must | M10: test/functional/ep01-04-data-leads-journeys.test.js | N10: 4.5 | O10: 2026-10-07
A11: FTC-007 | B11: EP-01 Data foundation and repair | C11: US-003: Correct an expiry with evidence | D11: data steward (PS-06) | E11: Correction requires evidence and is audited | F11: Given I hold permission "profile:update" | G11: When I PATCH /api/customers/30A12345/expiry with expiryDate "2027-05-10", insurer "PVI" and evidence "photo of certificate via hotline" | H11: Then the profile expiry is "2027-05-10" with confidence 0.9 And the audit trail contains "profile.expiry_corrected" with my user id and the evidence text And the lead is recomputed immediately | I11: As expected — all Then/And conditions asserted by the automated scenario. | J11: Pass | K11: FR-009, FR-097 | L11: Must | M11: test/functional/ep01-04-data-leads-journeys.test.js | N11: 5.1 | O11: 2026-10-07
A12: FTC-008 | B12: EP-01 Data foundation and repair | C12: US-003: Correct an expiry with evidence | D12: data steward (PS-06) | E12: Missing evidence | F12: — | G12: When I omit "evidence" | H12: Then the request fails validation | I12: As expected — all Then/And conditions asserted by the automated scenario. | J12: Pass | K12: FR-009, FR-097 | L12: Must | M12: test/functional/ep01-04-data-leads-journeys.test.js | N12: 3.2 | O12: 2026-10-07
A13: FTC-009 | B13: EP-01 Data foundation and repair | C13: US-004: Work the data-quality queue | D13: data steward (PS-06) | E13: Filter and resolve | F13: Given open DQ issues of types "reliable_expiry" and "conflicting_phone" | G13: When I GET /api/dq/issues?type=conflicting_phone When I POST /api/dq/issues/{id}/resolve with resolution "confirmed primary number by call" | H13: Then only "conflicting_phone" issues are returned with a byType summary Then the issue status is "resolved" with my id and timestamp | I13: As expected — all Then/And conditions asserted by the automated scenario. | J13: Pass | K13: FR-007 | L13: Must | M13: test/functional/ep01-04-data-leads-journeys.test.js | N13: 8.9 | O13: 2026-10-07
A14: FTC-010 | B14: EP-01 Data foundation and repair | C14: US-005: Platform-captured facts survive source reloads | D14: campaign manager (PS-03) | E14: Customer declaration beats a weaker reload | F14: Given a customer declared expiry "2027-01-15" (customer_declared, 0.8) | G14: When the nightly VETC batch re-ingests that plate with only a tag-anniversary estimate (0.25) | H14: Then the profile keeps expiry "2027-01-15" with method "customer_declared" | I14: As expected — all Then/And conditions asserted by the automated scenario. | J14: Pass | K14: FR-010 | L14: Must | M14: test/functional/ep01-04-data-leads-journeys.test.js | N14: 21.1 | O14: 2026-10-07
A15: FTC-011 | B15: EP-01 Data foundation and repair | C15: US-005: Platform-captured facts survive source reloads | D15: campaign manager (PS-03) | E15: Consent withdrawal survives reload | F15: Given the customer withdrew call consent in the consent centre | G15: When the source batch says callConsent = true | H15: Then the profile consent.call remains false | I15: As expected — all Then/And conditions asserted by the automated scenario. | J15: Pass | K15: FR-010 | L15: Must | M15: test/functional/ep01-04-data-leads-journeys.test.js | N15: 14.4 | O15: 2026-10-07
A16: FTC-012 | B16: EP-01 Data foundation and repair | C16: US-006: Infer vehicle category and premium | D16: campaign manager (PS-03) | E16: Declared seats beat toll class | F16: Given a vehicle with seatsDeclared 7 and tollClass 1, used personally | G16: — | H16: Then its category is "car_6_11" with confidence 0.85 And its lead premium is 873,400 VND incl. VAT for a 365-day term | I16: As expected — all Then/And conditions asserted by the automated scenario. | J16: Pass | K16: FR-006, FR-053 | L16: Must | M16: test/functional/ep01-04-data-leads-journeys.test.js | N16: 0.6 | O16: 2026-10-07
... A94: FTC-090 | B94: EP-10 Fleet / B2B | C94: US-054: Route company vehicles to account management | D94: fleet manager (PC-5) | E94: No B2C journeys for fleet (target behaviour) | F94: — | G94: — | H94: Then company-owned vehicles are not enrolled in renewal or conquest B2C journeys # Not yet enforced by journeys.json audiences — see doc 05 E-07 | I94: As expected — all Then/And conditions asserted by the automated scenario. | J94: Pass | K94: FR-015, FR-038, FR-070 | L94: Should | M94: test/functional/ep09-15-partners-claims-privacy-governance.test.js | N94: 1.9 | O94: 2026-10-07
A95: FTC-091 | B95: EP-10 Fleet / B2B | C95: US-055: Fleet renewal dashboard (planned) | D95: fleet manager (PC-5) | E95: Fleet view | F95: Given my company has 40 vehicles in the VETC base | G95: When I open the fleet dashboard | H95: Then I see each plate's cover status and expiry, sorted by soonest expiry And I can renew a selection in one order and receive one consolidated VAT invoice | I95: consolidated fleet dashboard is on the roadmap (benefit marked available=false) | J95: Not Run | K95: FR-070 | L95: Should | M95: test/functional/ep09-15-partners-claims-privacy-governance.test.js
A96: FTC-092 | B96: EP-11 Claims FNOL | C96: US-056: Report an accident from the app | D96: customer (PC-1) | E96: Valid FNOL | F96: Given I hold active policy "TAS-TNDSCA-2026-100123" valid from 2026-01-01 to 2026-12-31 | G96: When I POST /api/customer/claims with incidentDate "2026-10-05", description, location and photos 3 | H96: Then a claim "CL-XXXXXXXX" with status "submitted" and slaDueAt = now + 4 hours is created | I96: As expected — all Then/And conditions asserted by the automated scenario. | J96: Pass | K96: FR-071 | L96: Should | M96: test/functional/ep09-15-partners-claims-privacy-governance.test.js | N96: 5 | O96: 2026-10-07
A97: FTC-093 | B97: EP-11 Claims FNOL | C97: US-056: Report an accident from the app | D97: customer (PC-1) | E97: Outside policy period | F97: — | G97: When incidentDate is "2027-02-01" | H97: Then the request fails with "Incident date is outside the policy period" | I97: As expected — all Then/And conditions asserted by the automated scenario. | J97: Pass | K97: FR-071 | L97: Should | M97: test/functional/ep09-15-partners-claims-privacy-governance.test.js | N97: 2.6 | O97: 2026-10-07
A98: FTC-094 | B98: EP-11 Claims FNOL | C98: US-056: Report an accident from the app | D98: customer (PC-1) | E98: Not my policy | F98: — | G98: When I reference another customer's policy | H98: Then I receive 404 "Policy not found" | I98: As expected — all Then/And conditions asserted by the automated scenario. | J98: Pass | K98: FR-071 | L98: Should | M98: test/functional/ep09-15-partners-claims-privacy-governance.test.js | N98: 21.9 | O98: 2026-10-07
A99: FTC-095 | B99: EP-11 Claims FNOL | C99: US-057: Progress a claim | D99: claims handler (PS-07) | E99: Valid transition | F99: Given claim status "submitted" | G99: When I PATCH status "acknowledged" with a note | H99: Then history records the transition with my id and "claim.status_changed" is audited | I99: As expected — all Then/And conditions asserted by the automated scenario. | J99: Pass | K99: FR-072 | L99: Should | M99: test/functional/ep09-15-partners-claims-privacy-governance.test.js | N99: 99.1 | O99: 2026-10-07
A100: FTC-096 | B100: EP-11 Claims FNOL | C100: US-057: Progress a claim | D100: claims handler (PS-07) | E100: Skipping steps | F100: — | G100: When I PATCH a "submitted" claim to "paid" | H100: Then it fails with "Cannot move claim from submitted to paid" | I100: As expected — all Then/And conditions asserted by the automated scenario. | J100: Pass | K100: FR-072 | L100: Should | M100: test/functional/ep09-15-partners-claims-privacy-governance.test.js | N100: 3.8 | O100: 2026-10-07
A101: FTC-097 | B101: EP-11 Claims FNOL | C101: US-058: Track my claim | D101: customer (PC-1) | E101: My claims only | F101: — | G101: When I GET /api/customer/claims | H101: Then only claims for my profile are returned with current status and history | I101: As expected — all Then/And conditions asserted by the automated scenario. | J101: Pass | K101: FR-073 | L101: Should | M101: test/functional/ep09-15-partners-claims-privacy-governance.test.js | N101: 2.4 | O101: 2026-10-07
A102: FTC-098 | B102: EP-12 Privacy and consent | C102: US-059: Control how VETC contacts me | D102: customer (PC-1) | E102: Withdraw call consent | F102: — | G102: When I PUT /api/customer/consent with call = false | H102: Then no voice_bot or telesales contact is made to me And the change is audited as "consent.updated" and survives source reloads | I102: As expected — all Then/And conditions asserted by the automated scenario. | J102: Pass | K102: FR-078 | L102: Must | M102: test/functional/ep09-15-partners-claims-privacy-governance.test.js | N102: 23.4 | O102: 2026-10-07
A103: FTC-099 | B103: EP-12 Privacy and consent | C103: US-060: Download my data | D103: customer (PC-1) | E103: Self-service export | F103: — | G103: When I GET /api/customer/data-export | H103: Then I receive my profile, lead, policies, messages, source records (without internal hidden fields) and voice sessions And "dsar.access_exported" is audited | I103: As expected — all Then/And conditions asserted by the automated scenario. | J103: Pass | K103: FR-079 | L103: Must | M103: test/functional/ep09-15-partners-claims-privacy-governance.test.js | N103: 5.9 | O103: 2026-10-07
A104: FTC-100 | B104: EP-12 Privacy and consent | C104: US-061: Erase personal data lawfully | D104: compliance officer (PS-05) | E104: Active policy blocks erasure | F104: Given the customer has an active policy | G104: When I POST /api/dsar/{id}/erase | H104: Then it fails with "Active policy in force — personal data must be retained until expiry (legal obligation)" | I104: As expected — all Then/And conditions asserted by the automated scenario. | J104: Pass | K104: FR-080 | L104: Must | M104: test/functional/ep09-15-partners-claims-privacy-governance.test.js | N104: 78.7 | O104: 2026-10-07
A105: FTC-101 | B105: EP-12 Privacy and consent | C105: US-061: Erase personal data lawfully | D105: compliance officer (PS-05) | E105: Erasure | F105: Given no active policy | G105: When I erase | H105: Then name and phone are removed, consent becomes dnc, the lead is deleted, message text is "[erased]", transcripts are emptied And PII in handoffs and claims is also scrubbed # target — see doc 05 E-19 | I105: As expected — all Then/And conditions asserted by the automated scenario. | J105: Pass | K105: FR-080 | L105: Must | M105: test/functional/ep09-15-partners-claims-privacy-governance.test.js | N105: 10.4 | O105: 2026-10-07
A106: FTC-102 | B106: EP-12 Privacy and consent | C106: US-062: See only what my role needs | D106: campaign manager (PS-03) without PII permission | E106: Masking | F106: Given I lack "profile:read_pii" | G106: When I GET /api/customers/{id} | H106: Then name and phone are masked and piiMasked = true And "profile.viewed" is audited with piiVisible = false | I106: As expected — all Then/And conditions asserted by the automated scenario. | J106: Pass | K106: FR-081, FR-097 | L106: Must | M106: test/functional/ep09-15-partners-claims-privacy-governance.test.js | N106: 67.5 | O106: 2026-10-07
A107: FTC-103 | B107: EP-13 Rule governance | C107: US-063: Change scoring without a release | D107: rule author (PS-04) | E107: Invalid weights rejected | F107: — | G107: When I POST /api/rules/validate for kind "scoring" with weights summing to 95 | H107: Then errors include "factor weights must sum to 100 (got 95)" | I107: As expected — all Then/And conditions asserted by the automated scenario. | J107: Pass | K107: FR-057, FR-082, FR-083, FR-084 | L107: Must | M107: test/functional/ep09-15-partners-claims-privacy-governance.test.js | N107: 2.8 | O107: 2026-10-07
... A126: FTC-122 | B126: EP-15 Operations, insights and UX | C126: US-075: Apply data retention | D126: compliance officer (PS-05) | E126: Retention job | F126: — | G126: When the retention job runs | H126: Then source records older than 365 days and voice sessions older than 180 days are deleted And the job result lists each entity's action and cutoff date | I126: As expected — all Then/And conditions asserted by the automated scenario. | J126: Pass | K126: FR-105 | L126: Must | M126: test/functional/ep09-15-partners-claims-privacy-governance.test.js | N126: 3.2 | O126: 2026-10-07
A127: FTC-123 | B127: EP-15 Operations, insights and UX | C127: US-076: Work in my language | D127: telesales agent (PS-01) | E127: Language toggle | F127: — | G127: When I switch to "VI" | H127: Then all labels, help text and dates (dd/mm/yyyy) appear in Vietnamese without reloading And my choice is remembered on this device | I127: UI behaviour, verified manually / in UAT (VI ⇄ EN on staff console) | J127: Not Run | K127: FR-108, FR-110 | L127: Must | M127: test/functional/ep09-15-partners-claims-privacy-governance.test.js
A128: FTC-124 | B128: EP-15 Operations, insights and UX | C128: US-077: Verify a certificate at the roadside | D128: traffic police officer or inspection-centre clerk (external) | E128: Scan | F128: — | G128: When I scan the QR on the e-certificate | H128: Then /verify/{certNo} shows VALID or NOT VALID, product, masked plate, insurer and validity dates, in Vietnamese by default And the page works on a basic mobile browser without login | I128: physical QR scan of an e-certificate with a phone camera, verified in UAT | J128: Not Run | K128: FR-050, FR-109 | L128: Must | M128: test/functional/ep09-15-partners-claims-privacy-governance.test.js

Sheet Test Cases
A1: TASCO Growth Platform — Test Cases, Conditions & Results
A2: Execution run: 2026-10-07 · Build: branch claude/funny-cori-med8ed · Environment: CI-equivalent (Node 22, PostgreSQL 16, in-memory store for unit/API). Status legend in the "Read Me" sheet.
A4: Test Case ID | B4: Module | C4: Test Scenario | D4: Pre-conditions / Test Conditions | E4: Test Steps / Test Data | F4: Expected Result | G4: Actual Result | H4: Status | I4: Test Type | J4: Priority | K4: Automation / Evidence | L4: Known Issue Ref | M4: Executed On | N4: Executed By | O4: Environment
A5: TC-001 | B5: Authentication and session | C5: Password login for a role without MFA | D5: Demo seed; user exec | E5: POST /api/auth/login {username:"exec", password:<demo>} | F5: 200; accessToken, expiresIn=1800, user.permissions contains dashboard:read; audit auth.login | G5: As expected. Evidence: test/api/api.test.js (9/9 passed) | H5: Pass | I5: API | J5: P1 | K5: test/api/api.test.js | L5: — | M5: 2026-10-07 | N5: Automated (CI) | O5: CI (Node 22 / PostgreSQL 16)
A6: TC-002 | B6: Authentication and session | C6: MFA challenge for an MFA-required role | D6: User admin (TOTP enrolled) | E6: Login with the correct password | F6: 200 {mfaRequired:true, mfaToken}; no accessToken | G6: As expected. Evidence: test/api/api.test.js (9/9 passed) | H6: Pass | I6: API | J6: P1 | K6: test/api/api.test.js | L6: — | M6: 2026-10-07 | N6: Automated (CI) | O6: CI (Node 22 / PostgreSQL 16)
A7: TC-003 | B7: Authentication and session | C7: Complete MFA with a valid TOTP | D7: TC-002 done | E7: POST /api/auth/mfa {mfaToken, code:totp(secret)} | F7: 200; token claims amr:["pwd","otp"], aud:"staff"; failedLogins reset to 0 | G7: As expected. Evidence: test/api/api.test.js (9/9 passed) | H7: Pass | I7: API | J7: P1 | K7: test/api/api.test.js | L7: — | M7: 2026-10-07 | N7: Automated (CI) | O7: CI (Node 22 / PostgreSQL 16)
A8: TC-004 | B8: Authentication and session | C8: Wrong password is rejected without detail | D8: User exec | E8: Login with a wrong password | F8: 401 UNAUTHENTICATED "Invalid username or password"; audit auth.login_failed reason bad_password; failedLogins=1 | G8: As expected. Evidence: test/api/api.test.js (9/9 passed) | H8: Pass | I8: API | J8: P1 | K8: test/api/api.test.js | L8: — | M8: 2026-10-07 | N8: Automated (CI) | O8: CI (Node 22 / PostgreSQL 16)
A9: TC-005 | B9: Authentication and session | C9: Lockout after 5 failures | D9: User exec; LOCKOUT_MAX_FAILURES=5 | E9: 5 wrong passwords, then the correct password | F9: Attempts 1–5 → 401; attempt 6 → 423 ACCOUNT_LOCKED; audit auth.login_locked | G9: As expected. Evidence: test/security/security.test.js (12/12 passed) | H9: Pass | I9: Sec | J9: P1 | K9: test/security/security.test.js | L9: — | M9: 2026-10-07 | N9: Automated (CI) | O9: CI (Node 22 / PostgreSQL 16)
A10: TC-006 | B10: Authentication and session | C10: Lock expires after LOCKOUT_MINUTES | D10: TC-005; clock advanced 15 min (or LOCKOUT_MINUTES=0 in test config) | E10: Correct login | F10: 200; failedLogins=0, lockedUntil=null | G10: As expected. Evidence: test/security/security.test.js (12/12 passed) | H10: Pass | I10: Sec | J10: P2 | K10: test/security/security.test.js | L10: — | M10: 2026-10-07 | N10: Automated (CI) | O10: CI (Node 22 / PostgreSQL 16)
A11: TC-007 | B11: Authentication and session | C11: No username enumeration | D11: — | E11: Login with an unknown user, then a known user with a wrong password; compare | F11: Same 401 message; response times within ±30 % (the timing equaliser hashes a dummy password); audit actor anonymous | G11: As expected. Evidence: test/security/security.test.js (12/12 passed) | H11: Pass | I11: Sec | J11: P2 | K11: test/security/security.test.js | L11: — | M11: 2026-10-07 | N11: Automated (CI) | O11: CI (Node 22 / PostgreSQL 16)
A12: TC-008 | B12: Authentication and session | C12: MFA wrong code | D12: TC-002 | E12: POST /api/auth/mfa with code 000000 (or any wrong 6 digits) | F12: 401 "Invalid code"; audit auth.mfa_failed; failedLogins incremented | G12: As expected. Evidence: test/security/security.test.js (12/12 passed) | H12: Pass | I12: Sec | J12: P1 | K12: test/security/security.test.js | L12: — | M12: 2026-10-07 | N12: Automated (CI) | O12: CI (Node 22 / PostgreSQL 16)
A13: TC-009 | B13: Authentication and session | C13: MFA token expiry | D13: TC-002; clock +301 s | E13: Submit a valid code | F13: 401 "MFA session expired — sign in again" | G13: As expected. Evidence: test/api/api.test.js (9/9 passed) | H13: Pass | I13: API | J13: P2 | K13: test/api/api.test.js | L13: — | M13: 2026-10-07 | N13: Automated (CI) | O13: CI (Node 22 / PostgreSQL 16)
A14: TC-010 | B14: Authentication and session | C14: MFA self-enrolment for an MFA-required role | D14: Admin creates a user with role rule_approver (the seed is never shown to the admin; mustChangePassword:true) | E14: Login; scan otpauthUri; POST /api/auth/mfa with a valid code; change password | F14: Login → {mfaRequired:true, mfaEnrolment:true, otpauthUri}; first valid code completes enrolment (audit auth.mfa_enrolled) and returns mustChangePassword:true; next logins challenge without otpauthUri | G14: As expected. Evidence: test/api/api.test.js (9/9 passed) | H14: Pass | I14: API | J14: P1 | K14: test/api/api.test.js | L14: — | M14: 2026-10-07 | N14: Automated (CI) | O14: CI (Node 22 / PostgreSQL 16)
A15: TC-011 | B15: Authentication and session | C15: Disabled user is cut off immediately | D15: agent.hn holds a valid token | E15: Admin PATCH /api/users/:id {status:"disabled"}; agent calls GET /api/auth/me; agent logs in again | F15: me → 401 (status checked on every request; status/role/region changes also invalidate earlier tokens via tokensValidAfter); login → 401 reason inactive | G15: As expected. Evidence: test/api/api.test.js (9/9 passed) | H15: Pass | I15: API | J15: P1 | K15: test/api/api.test.js | L15: — | M15: 2026-10-07 | N15: Automated (CI) | O15: CI (Node 22 / PostgreSQL 16)
... A20: TC-016 | B20: Authentication and session | C20: Token audience confusion | D20: mfaToken from TC-002; customer token from POST /api/customer/session | E20: Use the mfaToken as a bearer on a staff route; use the customer token on GET /api/leads | F20: 401 for the mfaToken (aud:"mfa" rejected); 403 "Staff token required" for the customer token | G20: As expected. Evidence: test/security/security.test.js (12/12 passed) | H20: Pass | I20: Sec | J20: P1 | K20: test/security/security.test.js | L20: — | M20: 2026-10-07 | N20: Automated (CI) | O20: CI (Node 22 / PostgreSQL 16)
A21: TC-017 | B21: Authentication and session | C21: Logout revokes the token | D21: Logged-in exec | E21: POST /api/auth/logout, then GET /api/auth/me with the same token | F21: 401 on the same replica. *Note KI-07: per replica only.* | G21: Known issue KI-07 still open — expected behaviour not yet delivered; tracked in the KI register. | H21: Blocked | I21: API | J21: P2 | K21: test/api/api.test.js | L21: KI-07
A22: TC-018 | B22: Authentication and session | C22: Password policy and change | D22: exec token | E22: POST /api/auth/password with new password short; then with a wrong current password; then valid | F22: 400 "Password policy" (≥ 12 chars; must differ from the current one); 401 "Current password is incorrect"; 200 {reauthenticate:true} + audit auth.password_changed; the old token is rejected afterwards | G22: As expected. Evidence: test/api/api.test.js (9/9 passed) | H22: Pass | I22: API | J22: P2 | K22: test/api/api.test.js | L22: — | M22: 2026-10-07 | N22: Automated (CI) | O22: CI (Node 22 / PostgreSQL 16)
A23: TC-019 | B23: Authentication and session | C23: /api/auth/me reflects the RBAC mapping | D23: Each demo user | E23: GET /api/auth/me | F23: permissions equals the union of rbac.json for the user's roles | G23: As expected. Evidence: test/api/api.test.js (9/9 passed) | H23: Pass | I23: API | J23: P2 | K23: test/api/api.test.js | L23: — | M23: 2026-10-07 | N23: Automated (CI) | O23: CI (Node 22 / PostgreSQL 16)
A24: TC-020 | B24: Authentication and session | C24: MFA step honours lockout (KI-06) | D24: admin locked (5 failures) but holding an unexpired mfaToken | E24: POST /api/auth/mfa with a correct code | F24: 423 ACCOUNT_LOCKED; a replayed (already used) code → 401 "Invalid code" (KI-06 fixed) | G24: As expected. Evidence: test/security/security.test.js (12/12 passed) (fix for KI-06 verified) | H24: Pass | I24: Sec | J24: P2 | K24: test/security/security.test.js | L24: KI-06 | M24: 2026-10-07 | N24: Automated (CI) | O24: CI (Node 22 / PostgreSQL 16)
A25: TC-021 | B25: Authorisation (RBAC / ABAC) | C25: Full route × role authorisation matrix | D25: Tokens for all 13 staff roles + customer + partner | E25: For every route in the route table (76 at the time of writing), call it with each principal (minimal valid body) | F25: Route perm ∉ role permissions → 403 FORBIDDEN "Missing permission …"; no token → 401; public routes reachable without a token | G25: As expected. Evidence: test/api/api.test.js (9/9 passed) | H25: Pass | I25: API | J25: P1 | K25: test/api/api.test.js | L25: — | M25: 2026-10-07 | N25: Automated (CI) | O25: CI (Node 22 / PostgreSQL 16)
A26: TC-022 | B26: Authorisation (RBAC / ABAC) | C26: Segregation of duties for admin | D26: admin token | E26: GET /api/customers/:id; POST /api/rules; POST /api/rules/:id/approve | F26: 403 for all (admin has no profile:read, rules:author or rules:approve) | G26: As expected. Evidence: test/api/api.test.js (9/9 passed) | H26: Pass | I26: API | J26: P1 | K26: test/api/api.test.js | L26: — | M26: 2026-10-07 | N26: Automated (CI) | O26: CI (Node 22 / PostgreSQL 16)
A27: TC-023 | B27: Authorisation (RBAC / ABAC) | C27: Regional lead queue for agents | D27: agent.hn (region Hà Nội) | E27: GET /api/leads?region=TP.%20H%E1%BB%93%20Ch%C3%AD%20Minh | F27: Every item has region:"Hà Nội": the query region is overridden for users without dashboard:read | G27: As expected. Evidence: test/api/api.test.js (9/9 passed) | H27: Pass | I27: API | J27: P1 | K27: test/api/api.test.js | L27: — | M27: 2026-10-07 | N27: Automated (CI) | O27: CI (Node 22 / PostgreSQL 16)
A28: TC-024 | B28: Authorisation (RBAC / ABAC) | C28: ABAC region on Customer 360 | D28: agent.hn; profile in TP.HCM | E28: GET /api/customers/<hcm-id> | F28: 403 "Policy regional_data denies read on this profile" | G28: As expected. Evidence: test/security/security.test.js (12/12 passed) | H28: Pass | I28: Sec | J28: P1 | K28: test/security/security.test.js | L28: — | M28: 2026-10-07 | N28: Automated (CI) | O28: CI (Node 22 / PostgreSQL 16)
A29: TC-025 | B29: Authorisation (RBAC / ABAC) | C29: Agents see only their own or unassigned handoffs | D29: Handoff assigned to agent.hcm | E29: agent.hn: GET /api/handoffs/:id; PATCH it | F29: 403 (agent_own_handoffs); the list endpoint omits it | G29: As expected. Evidence: test/security/security.test.js (12/12 passed) | H29: Pass | I29: Sec | J29: P1 | K29: test/security/security.test.js | L29: — | M29: 2026-10-07 | N29: Automated (CI) | O29: CI (Node 22 / PostgreSQL 16)
A30: TC-026 | B30: Authorisation (RBAC / ABAC) | C30: Assignment requires supervisor | D30: Open handoff | E30: agent.hn PATCH {assignTo:"U-x"}; supervisor the same | F30: Agent → 403 "Missing permission handoff:assign"; supervisor → 200, audit handoff.updated | G30: As expected. Evidence: test/api/api.test.js (9/9 passed) | H30: Pass | I30: API | J30: P1 | K30: test/api/api.test.js | L30: — | M30: 2026-10-07 | N30: Automated (CI) | O30: CI (Node 22 / PostgreSQL 16)
A31: TC-027 | B31: Authorisation (RBAC / ABAC) | C31: No self-administration; separation of duties | D31: admin token | E31: PATCH /api/users/<self> {roles:["executive"]}; POST /api/users with roles ["rule_author","rule_approver"] | F31: 422 "You cannot change your own roles or status"; 422 "Separation of duties: rule_author and rule_approver cannot be held by the same person" | G31: As expected. Evidence: test/api/api.test.js (9/9 passed) | H31: Pass | I31: API | J31: P2 | K31: test/api/api.test.js | L31: — | M31: 2026-10-07 | N31: Automated (CI) | O31: CI (Node 22 / PostgreSQL 16)
A32: TC-028 | B32: Authorisation (RBAC / ABAC) | C32: Unknown role rejected | D32: admin | E32: POST /api/users with roles:["superuser"] | F32: 400 "Unknown role superuser" | G32: As expected. Evidence: test/api/api.test.js (9/9 passed) | H32: Pass | I32: API | J32: P2 | K32: test/api/api.test.js | L32: — | M32: 2026-10-07 | N32: Automated (CI) | O32: CI (Node 22 / PostgreSQL 16)
A33: TC-029 | B33: Authorisation (RBAC / ABAC) | C33: Region restriction beyond Customer 360 (KI-10) | D33: agent.hn; HCM profile | E33: GET /api/customers/<hcm-id>/lineage; POST /api/voice/sessions {profileId:<hcm-id>}; GET /api/policies?profileId=<hcm-id> | F33: Lineage → 403 (now enforced). Expected for voice sessions and policies: 403. *Currently 200: KI-10 (partly fixed)* | G33: Known issue KI-10 still open — expected behaviour not yet delivered; tracked in the KI register. | H33: Blocked | I33: Sec | J33: P2 | K33: test/security/security.test.js (todo KI-10) | L33: KI-10
A34: TC-030 | B34: Authorisation (RBAC / ABAC) | C34: Audience separation | D34: Staff token, customer token | E34: Staff token on GET /api/customer/home; customer token on GET /api/policies | F34: 403 "Customer token required"; 403 "Staff token required" | G34: As expected. Evidence: test/security/security.test.js (12/12 passed) | H34: Pass | I34: Sec | J34: P1 | K34: test/security/security.test.js | L34: — | M34: 2026-10-07 | N34: Automated (CI) | O34: CI (Node 22 / PostgreSQL 16)
A35: TC-031 | B35: Customer 360, data enrichment and MDM | C35: PII masking by permission | D35: campaign (no profile:read_pii), agent.hn (has it) | E35: GET /api/customers/:id as each | F35: Campaign: name/phone masked, piiMasked:true, message to omitted; agent: clear values. Audit profile.viewed with piiVisible false/true | G35: As expected. Evidence: test/api/api.test.js (9/9 passed) | H35: Pass | I35: API | J35: P1 | K35: test/api/api.test.js | L35: — | M35: 2026-10-07 | N35: Automated (CI) | O35: CI (Node 22 / PostgreSQL 16)
A36: TC-032 | B36: Customer 360, data enrichment and MDM | C36: Plate and phone normalisation on ingest | D36: steward token | E36: POST /api/data/ingest with plates 30a-123.45, 30A 12345, 30A.123.45, 30-12345 and phones +84912345678, 912345678, 0912 345 678 | F36: The first three plates map to key 30A12345; 30-12345 rejected with DQ invalid_plate; phones normalise to 0912345678; response rejected=1 | G36: As expected. Evidence: test/unit/identity.test.js (3/3 passed); test/integration/journeys.test.js (6/6 passed) | H36: Pass | I36: Int | J36: P1 | K36: test/unit/identity.test.js, test/integration/journeys.test.js | L36: — | M36: 2026-10-07 | N36: Automated (CI) | O36: CI (Node 22 / PostgreSQL 16)
A37: TC-033 | B37: Customer 360, data enrichment and MDM | C37: Survivorship across sources | D37: Same plate in vetc_account (trust 0.85) and partner_agent (0.5) with different names | E37: Ingest both | F37: Golden profile takes the higher-trust attribute; lineage lists both record IDs and sources | G37: As expected. Evidence: test/integration/journeys.test.js (6/6 passed) | H37: Pass | I37: Int | J37: P1 | K37: test/integration/journeys.test.js | L37: — | M37: 2026-10-07 | N37: Automated (CI) | O37: CI (Node 22 / PostgreSQL 16)
A38: TC-034 | B38: Customer 360, data enrichment and MDM | C38: Conflicting phones raise a DQ issue | D38: Two sources, same plate, different valid phones | E38: Ingest | F38: DQ issue <plate>:conflicting_phone open | G38: As expected. Evidence: test/integration/journeys.test.js (6/6 passed) | H38: Pass | I38: Int | J38: P2 | K38: test/integration/journeys.test.js | L38: — | M38: 2026-10-07 | N38: Automated (CI) | O38: CI (Node 22 / PostgreSQL 16)
A39: TC-035 | B39: Customer 360, data enrichment and MDM | C39: Customer-declared expiry survives rebuild | D39: Customer declared expiry (confidence 0.8) | E39: Re-ingest an older partner record for the plate (lower confidence) | F39: Profile keeps expiryMethod:"customer_declared" and its date | G39: As expected. Evidence: test/integration/journeys.test.js (6/6 passed) | H39: Pass | I39: Int | J39: P1 | K39: test/integration/journeys.test.js | L39: — | M39: 2026-10-07 | N39: Automated (CI) | O39: CI (Node 22 / PostgreSQL 16)
A40: TC-036 | B40: Customer 360, data enrichment and MDM | C40: Erased profiles are not re-identified | D40: Profile anonymised (TC-107) | E40: Ingest a new source record with name and phone for the same plate | F40: Profile stays anonymised:true with null name and phone | G40: As expected. Evidence: test/integration/governance.test.js (7/7 passed) | H40: Pass | I40: Int | J40: P1 | K40: test/integration/governance.test.js | L40: — | M40: 2026-10-07 | N40: Automated (CI) | O40: CI (Node 22 / PostgreSQL 16)
A41: TC-037 | B41: Customer 360, data enrichment and MDM | C41: Data steward expiry correction | D41: steward (MFA) | E41: PATCH /api/customers/:id/expiry {expiryDate, insurer, evidence:"Cert scan #123"}; then without evidence | F41: 200 + audit profile.expiry_corrected with evidence + lead recomputed; confidence = service_levels.stewardCorrectionConfidence (0.9); missing evidence → 400; a steward with a regional assignment is limited by ABAC regional_data (update) | G41: As expected. Evidence: test/api/api.test.js (9/9 passed) | H41: Pass | I41: API | J41: P1 | K41: test/api/api.test.js | L41: — | M41: 2026-10-07 | N41: Automated (CI) | O41: CI (Node 22 / PostgreSQL 16)
A42: TC-038 | B42: Customer 360, data enrichment and MDM | C42: DQ issue lifecycle | D42: Open invalid_plate issue | E42: POST /api/dq/issues/:id/resolve {resolution}; re-ingest the same bad record | F42: Status resolved with resolvedBy; the re-ingest reopens it (a resolved issue is re-raised when detected again) | G42: As expected. Evidence: test/api/api.test.js (9/9 passed) | H42: Pass | I42: API | J42: P2 | K42: test/api/api.test.js | L42: — | M42: 2026-10-07 | N42: Automated (CI) | O42: CI (Node 22 / PostgreSQL 16)
A43: TC-039 | B43: Customer 360, data enrichment and MDM | C43: Ingest input allow-list and bounds | D43: steward | E43: Batch of 5,001 records; batch with an extra field isAdmin:true; record without recordId | F43: 400 "at most 5000 items"; extra field stripped (not stored); 400 records[i].recordId required | G43: As expected. Evidence: test/api/api.test.js (9/9 passed) | H43: Pass | I43: API | J43: P2 | K43: test/api/api.test.js | L43: — | M43: 2026-10-07 | N43: Automated (CI) | O43: CI (Node 22 / PostgreSQL 16)
A44: TC-040 | B44: Customer 360, data enrichment and MDM | C44: Lineage view | D44: Profile built from 2 sources | E44: GET /api/customers/:id/lineage | F44: fields[] contains policy.expiryDate source and confidence; sourceRecords lists record IDs; recentBatches ≤ 10 | G44: As expected. Evidence: test/api/api.test.js (9/9 passed) | H44: Pass | I44: API | J44: P3 | K44: test/api/api.test.js | L44: — | M44: 2026-10-07 | N44: Automated (CI) | O44: CI (Node 22 / PostgreSQL 16)
A45: TC-041 | B45: Lead scoring, NBA and benefits | C45: Benefits pending legal review never reach customers | D45: benefits.json has loyalty_points pending_legal_review and an eligible profile | E45: GET /api/customer/home; GET /api/customers/:id (staff) | F45: Customer benefits[] excludes loyalty_points (pending legal review) and items flagged available:false (auto_renew, fleet_dashboard), and holds ≤ maxShown (3); the staff view includes them with legalStatus / available flags | G45: As expected. Evidence: test/api/api.test.js (9/9 passed) | H45: Pass | I45: API | J45: P1 | K45: test/api/api.test.js | L45: — | M45: 2026-10-07 | N45: Automated (CI) | O45: CI (Node 22 / PostgreSQL 16)
...

Sheet Automated Run
A1: Automated test execution — individual results
A3: Suite file | B3: Layer | C3: # | D3: Test scenario (as named in code) | E3: Result | F3: Duration (ms) | G3: Run date
A4: test/api/api.test.js | B4: API | C4: 1 | D4: health, readiness, metrics, OpenAPI and static assets | E4: Pass | F4: 1069.1 | G4: 2026-10-07
A5: test/api/api.test.js | B5: API | C5: 2 | D5: authentication and authorisation (401/403) and error envelope | E5: Pass | F5: 74.8 | G5: 2026-10-07
A6: test/api/api.test.js | B6: API | C6: 3 | D6: MFA login over HTTP and demo TOTP helper | E6: Pass | F6: 54 | G6: 2026-10-07
A7: test/api/api.test.js | B7: API | C7: 4 | D7: campaign manager journey: dashboard, leads, customer 360 (masked), journeys, events, voice campaign | E7: Pass | F7: 200.6 | G7: 2026-10-07
A8: test/api/api.test.js | B8: API | C8: 5 | D8: telesales agent: voice console → handoff → claim → quote → issue (idempotent) | E8: Pass | F8: 120.7 | G8: 2026-10-07
A9: test/api/api.test.js | B9: API | C9: 6 | D9: rule author + approver maker-checker over HTTP, with simulation | E9: Pass | F9: 148.9 | G9: 2026-10-07
A10: test/api/api.test.js | B10: API | C10: 7 | D10: partner API: API key auth, new-vehicle onboarding, bind, own policies, statement, IDOR protection | E10: Pass | F10: 83.4 | G10: 2026-10-07
A11: test/api/api.test.js | B11: API | C11: 8 | D11: customer app: signed-link session, home, declare expiry, quote, pay, consent, claim, export; IDOR blocked | E11: Pass | F11: 96.2 | G11: 2026-10-07
A12: test/api/api.test.js | B12: API | C12: 9 | D12: data steward, compliance (DSAR), auditor, admin and support endpoints | E12: Pass | F12: 593.6 | G12: 2026-10-07
A13: test/functional/ep01-04-data-leads-journeys.test.js | B13: Functional | C13: 1 | D13: US-001 · Duplicate records for the same vehicle merge into one golden profile | E13: Pass | F13: 1130.4 | G13: 2026-10-07
A14: test/functional/ep01-04-data-leads-journeys.test.js | B14: Functional | C14: 2 | D14: US-001 · Invalid plate is rejected and raised as a DQ issue | E14: Pass | F14: 5.4 | G14: 2026-10-07
A15: test/functional/ep01-04-data-leads-journeys.test.js | B15: Functional | C15: 3 | D15: US-001 · Batch size limit | E15: Pass | F15: 9.8 | G15: 2026-10-07
... A221: test/unit/voicebot.test.js | B221: Unit | C221: 11 | D221: unknown and lapsed expiry use the right script lines | E221: Pass | F221: 1.5 | G221: 2026-10-07

Sheet Read Me
A1: How to read this workbook
A3: Pass | B3: The automated suite that hosts the case ran in this execution with zero failures (see "Automated Run" for each individual test). The QA lead confirms per-case assertion coverage at each release.
A4: Fail | B4: The hosting automated suite reported at least one failure in this run.
A5: Blocked | B5: The expected result depends on a known issue (KI-xx in the test strategy register) that is still open.
A6: Not Run | B6: SIT, UAT, NFT/DR or manual case that needs production integrations, business users or a scheduled test window. Update Status, Actual Result, Executed On/By when executed.
A7: Pre-conditions / Test Conditions | B7: Data, user role and system state required before the steps. Demo users are listed in the separate access workbook (credentials are not stored here).
A8: Functional Test Cases | B8: Business scenarios from the user stories (docs/business/04): Given = pre-conditions, When = steps, Then = expected result. Every scenario is executed by test/functional/*.test.js against the real API; 3 scenarios are UI/physical checks or roadmap items and stay Not Run until UAT.
A9: Source | B9: Cases come from docs/quality/test-case-catalogue (164 cases, TC-001 – TC-164); automated results from test/unit, test/integration, test/api, test/security, test/pg and test/perf.
